Traceback (most recent call last):
  File "C:\Users\Andreas Sarkany\AppData\Roaming\Python\Python39\site-packages\jupyter_cache\executors\utils.py", line 51, in single_nb_execution
    executenb(
  File "c:\python39\lib\site-packages\nbclient\client.py", line 1112, in execute
    return NotebookClient(nb=nb, resources=resources, km=km, **kwargs).execute()
  File "c:\python39\lib\site-packages\nbclient\util.py", line 74, in wrapped
    return just_run(coro(*args, **kwargs))
  File "c:\python39\lib\site-packages\nbclient\util.py", line 53, in just_run
    return loop.run_until_complete(coro)
  File "c:\python39\lib\asyncio\base_events.py", line 642, in run_until_complete
    return future.result()
  File "c:\python39\lib\site-packages\nbclient\client.py", line 553, in async_execute
    await self.async_execute_cell(
  File "c:\python39\lib\site-packages\nbclient\client.py", line 857, in async_execute_cell
    self._check_raise_for_error(cell, exec_reply)
  File "c:\python39\lib\site-packages\nbclient\client.py", line 760, in _check_raise_for_error
    raise CellExecutionError.from_cell_and_msg(cell, exec_reply_content)
nbclient.exceptions.CellExecutionError: An error occurred while executing the following cell:
------------------

# StabilitÃ¤tskriterium
if Fo > 0.5:
    print("stability issue")

# Zeit
t = 0
while t < sim_time:
    # Randbedingungen bleiben gleich
    T[0] = 10
    T[n - 1] = 10
    # Berechnung innerhalb der DomÃ¤ne
    for i in range(1, n - 1):
        # Ergebnis fÃ¼r neuen Zeitschritt berechnen
        T_plus[i] = T[i] * (1 - 2 * Fo) + Fo * (T[i + 1] + T[i - 1])

    # Altes Temperaturfeld mit soeben berechnetem Ã¼berschreiben
    T = T_plus
    # Zeitschritt dazuzÃ¤hlen
    t += dt

fig, ax = plt.subplots()
line, = ax.plots([])

# plotting
x_pos = np.arange(0, L, dx)
plt.xlabel("x position [m]")
plt.ylabel("Temperature [Â°C]")
plt.plot(x_pos, T_plus, 'o-', alpha=0.65)
plt.show()
------------------

[1;31m---------------------------------------------------------------------------[0m
[1;31mAttributeError[0m                            Traceback (most recent call last)
[1;32m<ipython-input-4-6aa905dc5a19>[0m in [0;36m<module>[1;34m[0m
[0;32m     20[0m [1;33m[0m[0m
[0;32m     21[0m [0mfig[0m[1;33m,[0m [0max[0m [1;33m=[0m [0mplt[0m[1;33m.[0m[0msubplots[0m[1;33m([0m[1;33m)[0m[1;33m[0m[1;33m[0m[0m
[1;32m---> 22[1;33m [0mline[0m[1;33m,[0m [1;33m=[0m [0max[0m[1;33m.[0m[0mplots[0m[1;33m([0m[1;33m[[0m[1;33m][0m[1;33m)[0m[1;33m[0m[1;33m[0m[0m
[0m[0;32m     23[0m [1;33m[0m[0m
[0;32m     24[0m [1;31m# plotting[0m[1;33m[0m[1;33m[0m[1;33m[0m[0m

[1;31mAttributeError[0m: 'AxesSubplot' object has no attribute 'plots'
AttributeError: 'AxesSubplot' object has no attribute 'plots'

